<?xml version="1.0"?>
<robot name="robo_diferencial" xmlns:xacro="http://www.ros.org/wiki/xacro">

  <!-- ============================================ -->
  <!-- ARQUIVO PRINCIPAL                            -->
  <!-- Importa propriedades e macros, define o robô -->
  <!-- ============================================ -->

  <!-- ==================== -->
  <!-- IMPORTAÇÃO DE ARQUIVOS -->
  <!-- ==================== -->
  <!--
    xacro:include importa o conteúdo de outros arquivos .xacro
    $(find package_name) retorna o caminho do pacote ROS
  -->
  <xacro:include filename="$(find rm_description)/urdf/propriedades_robo.xacro"/>
  <xacro:include filename="$(find rm_description)/urdf/macros.xacro"/>

  <!-- ==================== -->
  <!-- BASE FOOTPRINT       -->
  <!-- ==================== -->
  <link name="base_footprint"/>

  <!-- ==================== -->
  <!-- BASE LINK            -->
  <!-- ==================== -->
  <link name="base_link">
    <visual>
      <origin xyz="0 0 0" rpy="0 0 0"/>
      <geometry>
        <cylinder radius="${base_radius}" length="${base_height}"/>
      </geometry>
      <material name="gray"/>
    </visual>
    <collision>
      <origin xyz="0 0 0" rpy="0 0 0"/>
      <geometry>
        <cylinder radius="${base_radius}" length="${base_height}"/>
      </geometry>
    </collision>
    <inertial>
      <origin xyz="0 0 0" rpy="0 0 0"/>
      <mass value="${base_mass}"/>
      <inertia
        ixx="${(1/12) * base_mass * (3*base_radius*base_radius + base_height*base_height)}"
        ixy="0.0" ixz="0.0"
        iyy="${(1/12) * base_mass * (3*base_radius*base_radius + base_height*base_height)}"
        iyz="0.0"
        izz="${(1/2) * base_mass * base_radius * base_radius}"/>
    </inertial>
  </link>

  <joint name="base_joint" type="fixed">
    <parent link="base_footprint"/>
    <child link="base_link"/>
    <origin xyz="0 0 ${base_height/2}" rpy="0 0 0"/>
  </joint>

  <!-- ==================== -->
  <!-- LINK 1 (usando macro) -->
  <!-- ==================== -->
  <!-- TAREFA: Chame o macro cylinder_link para criar o link1 -->
  <!-- Parâmetros: name, length, radius, mass, material -->
  <xacro:cylinder_link
    name="RodaEsc"
    length="${RodaEsc_length}"
    radius="${RodaEsc_radius}"
    mass="${RodaEsc_mass}"
    material="green"/>

  <joint name="jointEsc" type="continuous">
    <parent link="base_link"/>
    <child link="RodaEsc"/>
    <origin xyz="0 ${0.1 + base_height/2} 0" rpy="${pi/2} 0 0"/>
    <axis xyz="0 0 -1"/>
  </joint>

  <!-- ==================== -->
  <!-- LINK 2 (usando macro) -->
  <!-- ==================== -->
  <!-- TAREFA: Chame o macro cylinder_link para criar o link2 -->
  <xacro:cylinder_link
    name="RodaDir"
    length="${RodaDir_length}"
    radius="${RodaDir_radius}"
    mass="${RodaDir_mass}"
    material="RodaDir_material"/>

  <joint name="jointDir" type="continuous">
    <parent link="base_link"/>
    <child link="RodaDir"/>
    <origin xyz="0 -0.1 0" rpy="${pi/2} 0 0"/>
    <axis xyz="0 0 -1"/>
  </joint>

  <!-- ==================== -->
  <!-- END EFFECTOR         -->
  <!-- ==================== -->
  <!-- TAREFA: Use o macro sphere_link para criar o end_effector -->
  <xacro:sphere_link
    name="end_effector"
    radius="${end_effector_radius}"
    mass="${end_effector_mass}"
    material="end_effector_material"/>

  <joint name="end_effector_joint" type="fixed">
    <parent link="base_link"/>
    <child link="end_effector"/>
    <origin xyz="0 0 -0.1" rpy="0 0 0"/>
  </joint>

</robot>