<?xml version="1.0"?>
<robot name="robo_diferencial">
  <link name="base_footprint">
  </link>
  <link name="base_link">
    <visual>
      <origin xyz="0 0 0" rpy="0 0 0"/>
      <geometry>
        <cylinder radius="0.1" length="0.2"/>
      </geometry>
      <material name="gray">
        <color rgba="0.5 0.5 0.5 1"/>
      </material>
    </visual>

    <collision>
      <origin xyz="0 0 0" rpy="0 0 0"/>
      <geometry>
        <cylinder radius="0.1" length="0.05"/>
      </geometry>
    </collision>

    <inertial>
      <origin xyz="0 0 0" rpy="0 0 0"/>
      <mass value="2.0"/>
      <inertia
        ixx="0.01167"
        ixy="0.0" ixz="0.0"
        iyy="0.01167"
        iyz="0.0"
        izz="0.01"/>
    </inertial>
  </link>

  <joint name="base_joint" type="fixed">
    <parent link="base_footprint"/>
    <child link="base_link"/>
    <origin xyz="0 0 0.1" rpy="0 0 0"/>
  </joint>

  <link name="RodaEsc">
    <visual>
      <origin xyz="0 0 0" rpy="0 0 0"/>
      <geometry>
        <cylinder radius="0.2" length="0.1"/>
      </geometry>
      <material name="green">
        <color rgba="0 0.8 0.1 1"/>
      </material>
    </visual>

    <collision>
      <origin xyz="0 0 0" rpy="0 0 0"/>
      <geometry>
        <cylinder radius="0.2" length="0.1"/>
      </geometry>
    </collision>

    <inertial>
      <origin xyz="0 0 0" rpy="0 0 0"/>
      <mass value="1.0"/>
      <inertia
        ixx="0.01083"
        ixy="0.0" ixz="0.0"
        iyy="0.01083"
        iyz="0.0"
        izz="0.02"/>
    </inertial>
  </link>

  <joint name="jointEsc" type="continuous">
    <parent link="base_link"/>
    <child link="RodaEsc"/>
    <origin xyz="0 0.15 0" rpy="1.570795 0 0"/>
    <axis xyz="0 0 -1"/>
    <limit lower="-3.14159" upper="3.14159" effort="10" velocity="1.0"/>
  </joint>

  <link name="RodaDir">
    <visual>
      <origin xyz="0 0 0" rpy="0 0 0"/>
      <geometry>
        <cylinder radius="0.2" length="0.1"/>
      </geometry>
      <material name="green">
        <color rgba="0 0.8 0.1 1"/>
      </material>
    </visual>

    <collision>
      <origin xyz="0 0 0" rpy="0 0 0"/>
      <geometry>
        <cylinder radius="0.2" length="0.1"/>
      </geometry>
    </collision>

    <inertial>
      <origin xyz="0 0 0" rpy="0 0 0"/>
      <mass value="1.0"/>
      <inertia
        ixx="0.01083"
        ixy="0.0" ixz="0.0"
        iyy="0.01083"
        iyz="0.0"
        izz="0.02"/>
    </inertial>
  </link>

  <joint name="jointDir" type="continuous">
    <parent link="base_link"/>
    <child link="RodaDir"/>
    <origin xyz="0 -0.15 0" rpy="1.570795 0 0"/>
    <axis xyz="0 0 -1"/>
    <limit lower="-3.14159" upper="3.14159" effort="10" velocity="1.0"/>
  </joint>

  <link name="end_effector">
    <visual>
      <origin xyz="0 0 0" rpy="0 0 0"/>
      <geometry>
        <sphere radius="0.1"/>
      </geometry>
      <material name="gray">
        <color rgba="0.5 0.5 0.5 1"/>
      </material>
    </visual>

    <collision>
      <origin xyz="0 0 0" rpy="0 0 0"/>
      <geometry>
        <sphere radius="0.1"/>
      </geometry>
    </collision>

    <inertial>
      <origin xyz="0 0 0" rpy="0 0 0"/>
      <mass value="0.1"/>

      <inertia
        ixx="0.0004"
        ixy="0.0" ixz="0.0"
        iyy="0.0004"
        iyz="0.0"
        izz="0.0004"/>
    </inertial>
  </link>

  <joint name="end_effector_joint" type="fixed">
    <parent link="base_link"/>
    <child link="end_effector"/>
    <origin xyz="0 0 -0.1" rpy="0 0 0"/>
  </joint>


</robot>
