<?xml version="1.0"?>
<robot xmlns:xacro="http://www.ros.org/wiki/xacro">

    <xacro:macro name="wheel" params="prefix y_reflect">

        <joint name="${prefix}_wheel_joint" type="continuous">
            <parent link="base_link"/>
            <child link="${prefix}_wheel"/>
            <origin xyz="0 ${y_reflect * 0.175} 0" rpy="0 0 0"/>
            <axis xyz="0 1 0"/>
        </joint>

        <link name="${prefix}_wheel">
            <visual>
                <geometry>
                    <cylinder radius="0.05" length="0.04"/>
                </geometry>
                <origin xyz="0 0 0" rpy="${pi/2} 0 0"/>
            </visual>
            <collision>
                <geometry>
                    <cylinder radius="0.05" length="0.04"/>
                </geometry>
                <origin xyz="0 0 0" rpy="${pi/2} 0 0"/>
            </collision>
            <xacro:inertial_cylinder mass="0.1" length="0.04" radius="0.05">
                <origin xyz="0 0 0" rpy="${pi/2} 0 0"/>
            </xacro:inertial_cylinder>
        </link>

        <gazebo reference="${prefix}_wheel">
            <mu1 value="100000.0"/>
            <mu2 value="100000.0"/>
        </gazebo>

    </xacro:macro>

</robot>
